<?xml version="1.0"?>
<robot name="zoe">

  <link name="base_link">
   </link>

  <link name="sensor_ref">
    <visual>
      <origin xyz="0 0 0" rpy="0 0 -1.57" />
      <geometry>
        <mesh filename="package://experimental_package/models/zoe/meshes/zoe.dae"/>
      </geometry>
    </visual>
  </link>

  <link name="wfl">
    <visual>
      <origin xyz="0 0 0" rpy="0 0 -1.57" />
      <geometry>
        <mesh filename="package://experimental_package/models/zoe/cad/wheel/wheel.stl"/>
      </geometry>
      <material name="wheel_texture">
        <color rgba="0 0 0 1"/>
      </material>
    </visual>
  </link>

  <link name="wfr">
    <visual>
      <origin xyz="0 0 0" rpy="0 0 -1.57" />
      <geometry>
        <mesh filename="package://experimental_package/models/zoe/cad/wheel/wheel.stl"/>
      </geometry>
      <material name="wheel_texture">
        <color rgba="0 0 0 1"/>
      </material>
    </visual>
  </link>

  <link name="wrl">
    <visual>
      <origin xyz="0 0 0" rpy="0 0 -1.57" />
      <geometry>
        <mesh filename="package://experimental_package/models/zoe/cad/wheel/wheel.stl"/>
      </geometry>
      <material name="wheel_texture">
        <color rgba="0 0 0 1"/>
      </material>
    </visual>
  </link>

  <link name="wrr">
    <visual>
      <origin xyz="0 0 0" rpy="0 0 -1.57" />
      <geometry>
        <mesh filename="package://experimental_package/models/zoe/cad/wheel/wheel.stl"/>
      </geometry>
      <material name="wheel_texture">
        <color rgba="0 0 0 1"/>
      </material>
    </visual>
  </link>

  <link name="velodyne">
    <visual>
      <origin xyz="0.0 0.0 0.0" rpy="0 0 0" />
      <geometry>
        <mesh filename="package://experimental_package/models/zoe/meshes/velodyne/velodyne.dae"/>
      </geometry>
    </visual>
  </link>

  <link name="laserRear">
    <visual>
      <origin xyz="-0.07 -0.05 -0.023" rpy="0 0 0" />
      <geometry>
        <mesh filename="package://experimental_package/models/zoe/meshes/sick/sick.dae"/>
      </geometry>
    </visual>
  </link>

  <joint name="body_joint" type="continuous">
    <parent link="base_link"/>
    <child link="sensor_ref"/>
     <origin rpy="0 0 0" xyz="-1.3 0 0"/>
    <axis xyz="1 0 0"/>
  </joint>

  <joint name="fl_wheel_joint" type="continuous">
    <parent link="base_link"/>
    <child link="wfl"/>
    <origin rpy="0 0 0" xyz="1.3 0.8 0.4"/>
    <axis xyz="0 0 1" />
  </joint>

  <joint name="fr_wheel_joint" type="continuous">
    <parent link="base_link"/>
    <child link="wfr"/>
    <origin rpy="0 0 0" xyz="1.3 -0.8 0.4"/>
    <axis xyz="0 0 1" />
  </joint>

  <joint name="rl_wheel_joint" type="continuous">
    <parent link="base_link"/>
    <origin rpy="0 0 0" xyz="-1.3 0.8 0.4"/>
    <child link="wrl"/>
  </joint>

  <joint name="rr_wheel_joint" type="continuous">
    <parent link="base_link"/>
    <origin rpy="0 0 0" xyz="-1.3 -0.8 0.4"/>
    <child link="wrr"/>
  </joint>


  <joint name="rear_sick_joint" type="fixed">
    <parent link="sensor_ref"/>
    <child link="laserRear"/>
     <origin rpy="0 0 0" xyz="0 0 1.6"/>
  </joint>

  <joint name="velodyne_joint" type="fixed">
    <parent link="sensor_ref"/>
    <child link="velodyne"/>
    <origin rpy="0 0 0" xyz="1 0 1.6"/>
  </joint>
</robot>
