<?xml version="1.0"?>
<robot name="zoe">

  <link name="group2/base_link">
   </link>

  <link name="group2/sensor_ref">
    <visual>
      <origin xyz="0 0 0" rpy="0 0 -1.57" />
      <geometry>
        <mesh filename="package://experimental_package/models/zoe/meshes/zoe.dae"/>
      </geometry>
    </visual>
  </link>

  <link name="group2/wfl">
    <visual>
      <origin xyz="0 0 0" rpy="0 0 -1.57" />
      <geometry>
        <mesh filename="package://experimental_package/models/zoe/cad/wheel/wheel.stl"/>
      </geometry>
      <material name="wheel_texture">
        <color rgba="0 0 0 1"/>
      </material>
    </visual>
  </link>

  <link name="group2/wfr">
    <visual>
      <origin xyz="0 0 0" rpy="0 0 -1.57" />
      <geometry>
        <mesh filename="package://experimental_package/models/zoe/cad/wheel/wheel.stl"/>
      </geometry>
      <material name="wheel_texture">
        <color rgba="0 0 0 1"/>
      </material>
    </visual>
  </link>

  <link name="group2/wrl">
    <visual>
      <origin xyz="0 0 0" rpy="0 0 -1.57" />
      <geometry>
        <mesh filename="package://experimental_package/models/zoe/cad/wheel/wheel.stl"/>
      </geometry>
      <material name="wheel_texture">
        <color rgba="0 0 0 1"/>
      </material>
    </visual>
  </link>

  <link name="group2/wrr">
    <visual>
      <origin xyz="0 0 0" rpy="0 0 -1.57" />
      <geometry>
        <mesh filename="package://experimental_package/models/zoe/cad/wheel/wheel.stl"/>
      </geometry>
      <material name="wheel_texture">
        <color rgba="0 0 0 1"/>
      </material>
    </visual>
  </link>

  <link name="group2/velodyne">
    <visual>
      <origin xyz="0.0 0.0 0.0" rpy="0 0 0" />
      <geometry>
        <mesh filename="package://experimental_package/models/zoe/meshes/velodyne/velodyne.dae"/>
      </geometry>
    </visual>
  </link>

  <link name="group2/laserRear">
    <visual>
      <origin xyz="-0.07 -0.05 -0.023" rpy="0 0 0" />
      <geometry>
        <mesh filename="package://experimental_package/models/zoe/meshes/sick/sick.dae"/>
      </geometry>
    </visual>
  </link>

  <joint name="body_joint" type="continuous">
    <parent link="group2/base_link"/>
    <child link="group2/sensor_ref"/>
     <origin rpy="0 0 0" xyz="-1.3 0 0"/>
    <axis xyz="1 0 0"/>
  </joint>

  <joint name="fl_wheel_joint" type="continuous">
    <parent link="group2/base_link"/>
    <child link="group2/wfl"/>
    <origin rpy="0 0 0" xyz="1.3 0.8 0.4"/>
    <axis xyz="0 0 1" />
  </joint>

  <joint name="fr_wheel_joint" type="continuous">
    <parent link="group2/base_link"/>
    <child link="group2/wfr"/>
    <origin rpy="0 0 0" xyz="1.3 -0.8 0.4"/>
    <axis xyz="0 0 1" />
  </joint>

  <joint name="rl_wheel_joint" type="continuous">
    <parent link="group2/base_link"/>
    <origin rpy="0 0 0" xyz="-1.3 0.8 0.4"/>
    <child link="group2/wrl"/>
  </joint>

  <joint name="rr_wheel_joint" type="continuous">
    <parent link="group2/base_link"/>
    <origin rpy="0 0 0" xyz="-1.3 -0.8 0.4"/>
    <child link="group2/wrr"/>
  </joint>


  <joint name="rear_sick_joint" type="fixed">
    <parent link="group2/sensor_ref"/>
    <child link="group2/laserRear"/>
     <origin rpy="0 0 0" xyz="0 0 1.6"/>
  </joint>

  <joint name="velodyne_joint" type="fixed">
    <parent link="group2/sensor_ref"/>
    <child link="group2/velodyne"/>
    <origin rpy="0 0 0" xyz="1 0 1.6"/>
  </joint>
</robot>
